<?xml version="1.0" ?>
<robot
  name="XM_3_URDF_2">

  <!--link base_link-->
  <link
    name="base_link">
    <inertial>
      <origin
        xyz="-0.03776 -0.00084976 0.016292"
        rpy="0 0 0" />
      <mass
        value="18.845" />
      <inertia
        ixx="1.4988"
        ixy="-0.0076372"
        ixz="-0.11172"
        iyy="1.5111"
        iyz="0.011979"
        izz="0.39888" />
    </inertial>
    <visual>
      <origin
        xyz="0 0 0"
        rpy="0 0 0" />
      <geometry>
        <mesh
          filename="package://xm_urdf/meshes/old_arm/base_link.STL" />
      </geometry>
      <material
        name="">
        <color
          rgba="0.2 0.75294 0.75294 1" />
      </material>
    </visual>
    <collision>
      <origin
        xyz="0 0 0"
        rpy="0 0 0" />
      <geometry>
        <mesh
          filename="package://xm_urdf/meshes/old_arm/base_link.STL" />
      </geometry>
    </collision>
  </link>

<!--link : link_elecatork-->
  <link
    name="link_elecator">
    <inertial>
      <origin
        xyz="0.042541 1.0533E-10 0.0015023"
        rpy="0 0 0" />
      <mass
        value="3.259" />
      <inertia
        ixx="0.022091"
        ixy="-2.6206E-16"
        ixz="0.00039271"
        iyy="0.020562"
        iyz="-7.2237E-17"
        izz="0.0089044" />
    </inertial>
    <visual>
      <origin
        xyz="0 0 0"
        rpy="0 0 0" />
      <geometry>
        <mesh
          filename="package://xm_urdf/meshes/old_arm/link_elecator.STL" />
      </geometry>
      <material
        name="">
        <color
          rgba="0.89804 0.2 0.92941 1" />
      </material>
    </visual>
    <collision>
      <origin
        xyz="0 0 0"
        rpy="0 0 0" />
      <geometry>
        <mesh
          filename="package://xm_urdf/meshes/old_arm/link_elecator.STL" />
      </geometry>
    </collision>
  </link>

<!--joint : joint_elecator-->
<!--parent:base_link-->
<!--child: link_elecator-->
  <joint
    name="joint_elecator"
    type="prismatic">
    <origin
      xyz="-0.057235 0 0.15056"
      rpy="-3.8337E-16 2.2077E-17 1.4935E-14" />
    <parent
      link="base_link" />
    <child
      link="link_elecator" />
    <axis
      xyz="0 0 -1" />
    <limit
      lower="-0.14"
      upper="-0.5"
      effort="0"
      velocity="0" />
  </joint>

<!--link : link_waist-->

  <link
    name="link_waist">
    <inertial>
      <origin
        xyz="0.073302 0.00035771 0.004568"
        rpy="0 0 0" />
      <mass
        value="2.6855" />
      <inertia
        ixx="0.015465"
        ixy="0.00013759"
        ixz="-0.00086987"
        iyy="0.018699"
        iyz="8.736E-05"
        izz="0.014831" />
    </inertial>
    <visual>
      <origin
        xyz="0 0 0"
        rpy="0 0 0" />
      <geometry>
        <mesh
          filename="package://xm_urdf/meshes/old_arm/link_waist.STL" />
      </geometry>
      <material
        name="">
        <color
          rgba="0.89804 0.91765 0.2 1" />
      </material>
    </visual>
    <collision>
      <origin
        xyz="0 0 0"
        rpy="0 0 0" />
      <geometry>
        <mesh
          filename="package://xm_urdf/meshes/old_arm/link_waist.STL" />
      </geometry>
    </collision>
  </link>

<!--joint : joint_waist-->
<!--parent:link_elecator-->
<!--child:link_waist-->
  <joint
    name="joint_waist"
    type="revolute">
    <origin
      xyz="0.105 0 0.0035"
      rpy="6.8618E-17 6.2554E-31 -1.6061E-15" />
    <parent
      link="link_elecator" />
    <child
      link="link_waist" />
    <axis
      xyz="0 0 1" />
    <limit
      lower="-1.04"
      upper="1.04"
      effort="0"
      velocity="0" />
  </joint>

  <!--link : link_big_arm-->
  <link
    name="link_big_arm">
    <inertial>
      <origin
        xyz="0.1981 -0.0038857 0.0039628"
        rpy="0 0 0" />
      <mass
        value="1.0832" />
      <inertia
        ixx="0.0026099"
        ixy="0.00013064"
        ixz="0.00027499"
        iyy="0.014832"
        iyz="2.6134E-06"
        izz="0.016351" />
    </inertial>
    <visual>
      <origin
        xyz="0 0 0"
        rpy="0 0 0" />
      <geometry>
        <mesh
          filename="package://xm_urdf/meshes/old_arm/link_big_arm.STL" />
      </geometry>
      <material
        name="">
        <color
          rgba="0.2 0.2 0.92941 1" />
      </material>
    </visual>
    <collision>
      <origin
        xyz="0 0 0"
        rpy="0 0 0" />
      <geometry>
        <mesh
          filename="package://xm_urdf/meshes/old_arm/link_big_arm.STL" />
      </geometry>
    </collision>
  </link>

<!--joint:joint_big_arm-->
<!--parent:link_waist-->
<!--child:link_big_arm-->

  <joint
    name="joint_big_arm"
    type="revolute">
    <origin
      xyz="0.15678 0 -0.0215"
      rpy="7.9575E-19 1.2761E-15 1.7823E-18" />
    <parent
      link="link_waist" />
    <child
      link="link_big_arm" />
    <axis
      xyz="0 -1 0" />
    <limit
      lower="-1.57"
      upper="1.57"
      effort="0"
      velocity="0" />
  </joint>

<!--link :link_forearm-->

  <link
    name="link_forearm">
    <inertial>
      <origin
        xyz="0.13987 -0.00071189 0.0027737"
        rpy="0 0 0" />
      <mass
        value="0.49305" />
      <inertia
        ixx="0.00053223"
        ixy="-3.1954E-06"
        ixz="7.0538E-05"
        iyy="0.0038625"
        iyz="-7.2409E-08"
        izz="0.0040628" />
    </inertial>
    <visual>
      <origin
        xyz="0 0 0"
        rpy="0 0 0" />
      <geometry>
        <mesh
          filename="package://xm_urdf/meshes/old_arm/link_forearm.STL" />
      </geometry>
      <material
        name="">
        <color
          rgba="0.2 0.91765 0.2 1" />
      </material>
    </visual>
    <collision>
      <origin
        xyz="0 0 0"
        rpy="0 0 0" />
      <geometry>
        <mesh
          filename="package://xm_urdf/meshes/old_arm/link_forearm.STL" />
      </geometry>
    </collision>
  </link>

<!--joint:joint_forearm-->
<!--parent:link_big_arm-->
<!--child:link_forearm-->

  <joint
    name="joint_forearm"
    type="revolute">
    <origin
      xyz="0.34993 0 0.007"
      rpy="-7.9575E-19 2.498E-16 -1.41E-16" />
    <parent
      link="link_big_arm" />
    <child
      link="link_forearm" />
    <axis
      xyz="0 -1 0" />
    <limit
      lower="-2.4"
      upper="2.4"
      effort="0"
      velocity="0" />
  </joint>

<!--link: link_wrist_pitching-->

  <link
    name="link_wrist_pitching">
    <inertial>
      <origin
        xyz="0.00026963 1.305E-06 -5.9807E-09"
        rpy="0 0 0" />
      <mass
        value="0.061446" />
      <inertia
        ixx="1.8713E-05"
        ixy="-1.966E-11"
        ixz="2.848E-12"
        iyy="3.8634E-06"
        iyz="-4.7509E-13"
        izz="1.8809E-05" />
    </inertial>
    <visual>
      <origin
        xyz="0 0 0"
        rpy="0 0 0" />
      <geometry>
        <mesh
          filename="package://xm_urdf/meshes/old_arm/link_wrist_pitching.STL" />
      </geometry>
      <material
        name="">
        <color
          rgba="0.9 0.2 0.2 1" />
      </material>
    </visual>
    <collision>
      <origin
        xyz="0 0 0"
        rpy="0 0 0" />
      <geometry>
        <mesh
          filename="package://xm_urdf/meshes/old_arm/link_wrist_pitching.STL" />
      </geometry>
    </collision>
  </link>

<!--joint:joint_wrist_pitching-->
<!--parent:link_forearm-->
<!--child:link_wrist_pitching-->

  <joint
    name="joint_wrist_pitching"
    type="revolute">
    <origin
      xyz="0.29994 0 0.006"
      rpy="-8.7263E-32 -1.3878E-16 1.3922E-16" />
    <parent
      link="link_forearm" />
    <child
      link="link_wrist_pitching" />
    <axis
      xyz="0 1 0" />
    <limit
      lower="-1.57"
      upper="1.57"
      effort="0"
      velocity="0" />
  </joint>

  <!--link: link_wrist_rotation-->
  <link
    name="link_wrist_rotation">
    <inertial>
      <origin
        xyz="0.041451 0.0036734 0.0066551"
        rpy="0 0 0" />
      <mass
        value="0.37001" />
      <inertia
        ixx="0.00049563"
        ixy="6.5715E-06"
        ixz="-1.9426E-05"
        iyy="0.00044476"
        iyz="-9.3638E-06"
        izz="0.00072614" />
    </inertial>
    <visual>
      <origin
        xyz="0 0 0"
        rpy="0 0 0" />
      <geometry>
        <mesh
          filename="package://xm_urdf/meshes/old_arm/link_wrist_rotation.STL" />
      </geometry>
      <material
        name="">
        <color
          rgba="0.9 0.2 0.2 1" />
      </material>
    </visual>
    <collision>
      <origin
        xyz="0 0 0"
        rpy="0 0 0" />
      <geometry>
        <mesh
          filename="package://xm_urdf/meshes/old_arm/link_wrist_rotation.STL" />
      </geometry>
    </collision>
  </link>

  <!--joint:joint_wrist_rotation-->
  <!--parent:link_wrist_pitching-->
  <!--child:link_wrist_rotation-->
  <joint
    name="joint_wrist_rotation"
    type="revolute">
    <origin
      xyz="0.061043 0 0"
      rpy="-5.2036E-17 1.5448E-16 0" />
    <parent
      link="link_wrist_pitching" />
    <child
      link="link_wrist_rotation" />
    <axis
      xyz="1 0 0" />
    <limit
      lower="-3.14"
      upper="3.14"
      effort="0"
      velocity="0" />
  </joint>

  <!--link:link_Left_Finger-->
  <link
    name="link_Left_Finger">
    <inertial>
      <origin
        xyz="0.020988 0.012659 -0.015939"
        rpy="0 0 0" />
      <mass
        value="0.024166" />
      <inertia
        ixx="3.8547E-06"
        ixy="-3.2779E-06"
        ixz="-1.8373E-06"
        iyy="2.7619E-05"
        iyz="2.8362E-07"
        izz="2.7872E-05" />
    </inertial>
    <visual>
      <origin
        xyz="0 0 0"
        rpy="0 0 0" />
      <geometry>
        <mesh
          filename="package://xm_urdf/meshes/old_arm/link_Left_Finger.STL" />
      </geometry>
      <material
        name="">
        <color
          rgba="0.94 0 0.94 1" />
      </material>
    </visual>
    <collision>
      <origin
        xyz="0 0 0"
        rpy="0 0 0" />
      <geometry>
        <mesh
          filename="package://xm_urdf/meshes/old_arm/link_Left_Finger.STL" />
      </geometry>
    </collision>
  </link>

  <!--joint-->
  <joint
    name="joint_Left_Finger"
    type="prismatic">
    <origin
      xyz="0.104 0.0012665 0.0185"
      rpy="2.6888E-16 0 0" />
    <parent
      link="link_wrist_rotation" />
    <child
      link="link_Left_Finger" />
    <axis
      xyz="0 -1 0" />
    <limit
      lower="-0.05"
      upper="0"
      effort="0"
      velocity="0" />
  </joint>

  <!--link-->
  <link
    name="link_Rihgt_finger">
    <inertial>
      <origin
        xyz="0.020988 -0.012659 -0.01594"
        rpy="0 0 0" />
      <mass
        value="0.024166" />
      <inertia
        ixx="3.8548E-06"
        ixy="3.2779E-06"
        ixz="-1.8372E-06"
        iyy="2.7619E-05"
        iyz="-2.8386E-07"
        izz="2.7872E-05" />
    </inertial>
    <visual>
      <origin
        xyz="0 0 0"
        rpy="0 0 0" />
      <geometry>
        <mesh
          filename="package://xm_urdf/meshes/old_arm/link_Rihgt_finger.STL" />
      </geometry>
      <material
        name="">
        <color
          rgba="0.94 0 0.94 1" />
      </material>
    </visual>
    <collision>
      <origin
        xyz="0 0 0"
        rpy="0 0 0" />
      <geometry>
        <mesh
          filename="package://xm_urdf/meshes/old_arm/link_Rihgt_finger.STL" />
      </geometry>
    </collision>
  </link>
<!--joint-->
  <joint
    name="joint_Rihgt_finger"
    type="prismatic">
    <origin
      xyz="0.104 -0.0012665 0.0185"
      rpy="3.0821E-14 -1.5637E-15 6.4697E-17" />
    <parent
      link="link_wrist_rotation" />
    <child
      link="link_Rihgt_finger" />
    <axis
      xyz="0 -1 0" />
    <limit
      lower="0"
      upper="0.05"
      effort="0"
      velocity="0" />
  </joint>

  <!--link-->
  <link
    name="link_PTZ_Y">
    <inertial>
      <origin
        xyz="-0.013205 -2.2204E-16 0.0023935"
        rpy="0 0 0" />
      <mass
        value="0.051533" />
      <inertia
        ixx="9.5339E-06"
        ixy="-4.7384E-20"
        ixz="-2.2135E-07"
        iyy="1.385E-05"
        iyz="5.7514E-22"
        izz="1.4695E-05" />
    </inertial>
    <visual>
      <origin
        xyz="0 0 0"
        rpy="0 0 0" />
      <geometry>
        <mesh
          filename="package://xm_urdf/meshes/old_arm/link_PTZ_Y.STL" />
      </geometry>
      <material
        name="">
        <color
          rgba="0.9 0.5 0.2 1" />
      </material>
    </visual>
    <collision>
      <origin
        xyz="0 0 0"
        rpy="0 0 0" />
      <geometry>
        <mesh
          filename="package://xm_urdf/meshes/old_arm/link_PTZ_Y.STL" />
      </geometry>
    </collision>
  </link>

  <!--joint-->
  <joint
    name="joint_PTZ_Y"
    type="revolute">
    <origin
      xyz="-0.042735 0 1.02"
      rpy="-6.1232E-17 1.5434E-14 1.088E-14" />
    <parent
      link="base_link" />
    <child
      link="link_PTZ_Y" />
    <axis
      xyz="0 1 0" />
    <limit
      lower="-1.04"
      upper="1.04"
      effort="0"
      velocity="0" />
  </joint>

  <!--link-->
  <link
    name="link_Kinect">
    <inertial>
      <origin
        xyz="-0.018191 -1.1102E-16 -0.022845"
        rpy="0 0 0" />
      <mass
        value="0.23988" />
      <inertia
        ixx="0.00071306"
        ixy="4.4067E-18"
        ixz="-4.7665E-07"
        iyy="0.00032244"
        iyz="5.003E-20"
        izz="0.00045575" />
    </inertial>
    <visual>
      <origin
        xyz="0 0 0"
        rpy="0 0 0" />
      <geometry>
        <mesh
          filename="package://xm_urdf/meshes/old_arm/link_Kinect.STL" />
      </geometry>
      <material
        name="">
        <color
          rgba="0.2 0.2 0.2 1" />
      </material>
    </visual>
    <collision>
      <origin
        xyz="0 0 0"
        rpy="0 0 0" />
      <geometry>
        <mesh
          filename="package://xm_urdf/meshes/old_arm/link_Kinect.STL" />
      </geometry>
    </collision>

    <!--joint-->
  </link>
  <joint
    name="joint_Kinect"
    type="revolute">
    <origin
      xyz="0.017 0 0.1265"
      rpy="-3.0177E-33 0 0" />
    <parent
      link="link_PTZ_Y" />
    <child
      link="link_Kinect" />
    <axis
      xyz="0 0 1" />
    <limit
      lower="-1.57"
      upper="1.57"
      effort="0"
      velocity="0" />
  </joint>
  
  <joint
    name="gripper_joint" type="fixed">
    <origin rpy="-1.570795 0 0" xyz="0.05 0 -0.008"/>
    <parent link="link_wrist_rotation"/>
    <child link="gripper_link"/>
  </joint>

  <link 
    name="gripper_link">
    <visual>
      <origin rpy="0 0 0" xyz="-0.05 0 0"/>
      <geometry>
        <box size="0.001 0.001 0.001"/>
      </geometry>
    </visual>
    <collision>
      <origin rpy="0 0 0" xyz="-0.05 0 0"/>
      <geometry>
        <box size="0.001 0.001 0.001"/>
      </geometry>
    </collision>
    <!--inertial>
         <mass value="0.0012" />
         <origin xyz="0 0 0"/>
         <inertia ixx="2e-8" ixy="0.0" ixz="0.0"
          iyy="2e-8" iyz="0.0"
          izz="2e-8" />
      </inertial -->
  </link>
</robot>